Workbook

Sheet Catalogue
A1: Engineering and IT software catalogue
A3: Entries | B3: =COUNTA(A6:A985) -> 480 | D3: Unranked shortlists · research date 7 October 2026 · IT rows shaded
A5: Field ID | B5: Product / module / toolchain | C5: Access | D5: Best-fit job | E5: Boundary to check | F5: Implementation / hypothesis | G5: User / extension language | H5: Language evidence | I5: Source coverage | J5: Official discovery link | K5: Retrieved source / research lead | L5: Language evidence link
A6: E01 | B6: ETAP | C6: P | D6: Industrial network studies | E6: Capabilities depend on modules | F6: Hypothesis: C/C++ and/or Fortran numerical kernels; mixed UI | G6: Product-specific scripting, UDFs and input decks | H6: Architecture hypothesis only | I6: Product/family reference | J6: =HYPERLINK("https://etap.com/solutions/power-system-analysis","Official site") -> Official site | K6: =HYPERLINK("https://etap.com/product/load-flow-software","Evidence / lead") -> Evidence / lead | L6: =HYPERLINK("https://www.ansys.com/products","Language source") -> Language source
A7: E01 | B7: DIgSILENT PowerFactory | C7: P | D7: Transmission and distribution studies | E7: Detailed models require specialist setup | F7: Hypothesis: C/C++ and/or Fortran numerical kernels; mixed UI | G7: Product-specific scripting, UDFs and input decks | H7: Architecture hypothesis only | I7: Product/family reference | J7: =HYPERLINK("https://www.digsilent.de/en/functions.html","Official site") -> Official site | K7: =HYPERLINK("https://www.digsilent.de/en/faq-reader-powerfactory/where-can-i-get-an-overview-list-showing-all-powerfactory-functions.html","Evidence / lead") -> Evidence / lead | L7: =HYPERLINK("https://www.ansys.com/products","Language source") -> Language source
A8: E01 | B8: PSS E | C8: P | D8: Transmission planning and dynamics | E8: Not a complete industrial electrical design package | F8: Hypothesis: C/C++ and/or Fortran numerical kernels; mixed UI | G8: Product-specific scripting, UDFs and input decks | H8: Architecture hypothesis only | I8: Vendor-level reference | J8: =HYPERLINK("https://www.siemens.com/","Official site") -> Official site | K8: =HYPERLINK("https://www.siemens.com/en-gb/products/tia-portal/step7/","Evidence / lead") -> Evidence / lead | L8: =HYPERLINK("https://www.ansys.com/products","Language source") -> Language source
A9: E01 | B9: PowerWorld Simulator | C9: P | D9: Network visualization and transmission analysis | E9: Check distribution and dynamics requirements | F9: Hypothesis: C/C++ and/or Fortran numerical kernels; mixed UI | G9: Product-specific scripting, UDFs and input decks | H9: Architecture hypothesis only | I9: Product/family reference | J9: =HYPERLINK("https://www.powerworld.com/","Official site") -> Official site | K9: =HYPERLINK("https://www.powerworld.com/","Evidence / lead") -> Evidence / lead | L9: =HYPERLINK("https://www.ansys.com/products","Language source") -> Language source
A10: E01 | B10: CYME | C10: P | D10: Distribution network analysis | E10: Licensed modules determine coverage | F10: Hypothesis: C/C++ and/or Fortran numerical kernels; mixed UI | G10: Product-specific scripting, UDFs and input decks | H10: Architecture hypothesis only | I10: Candidate: direct verification pending | J10: =HYPERLINK("https://www.cyme.com/","Official site") -> Official site | K10: =HYPERLINK("https://www.cyme.com/","Evidence / lead") -> Evidence / lead | L10: =HYPERLINK("https://www.ansys.com/products","Language source") -> Language source
A11: E01 | B11: Synergi Electric | C11: P | D11: Distribution planning | E11: Utility data preparation remains substantial | F11: Hypothesis: C/C++ and/or Fortran numerical kernels; mixed UI | G11: Product-specific scripting, UDFs and input decks | H11: Architecture hypothesis only | I11: Vendor-level reference | J11: =HYPERLINK("https://www.dnv.com/","Official site") -> Official site | K11: =HYPERLINK("https://www.dnv.com/","Evidence / lead") -> Evidence / lead | L11: =HYPERLINK("https://www.ansys.com/products","Language source") -> Language source
A12: E01 | B12: SKM PowerTools | C12: P | D12: Industrial power system studies | E12: Study types and device libraries need checking | F12: Hypothesis: C/C++ and/or Fortran numerical kernels; mixed UI | G12: Product-specific scripting, UDFs and input decks | H12: Architecture hypothesis only | I12: Product/family reference | J12: =HYPERLINK("https://www.skm.com/","Official site") -> Official site | K12: =HYPERLINK("https://www.skm.com/","Evidence / lead") -> Evidence / lead | L12: =HYPERLINK("https://www.ansys.com/products","Language source") -> Language source
A13: E01 | B13: NEPLAN | C13: P | D13: Electrical network analysis | E13: Verify edition and solver options | F13: Hypothesis: C/C++ and/or Fortran numerical kernels; mixed UI | G13: Product-specific scripting, UDFs and input decks | H13: Architecture hypothesis only | I13: Candidate: direct verification pending | J13: =HYPERLINK("https://www.neplan.ch/","Official site") -> Official site | K13: =HYPERLINK("https://www.neplan.ch/","Evidence / lead") -> Evidence / lead | L13: =HYPERLINK("https://www.ansys.com/products","Language source") -> Language source
A14: E01 | B14: OpenDSS | C14: O | D14: Unbalanced distribution simulation | E14: Engineering interface work remains | F14: Delphi/Object Pascal; Free Pascal in OpenDSSCmd | G14: DSS commands; external automation interfaces | H14: Official project distribution documentation | I14: Product/family reference | J14: =HYPERLINK("https://sourceforge.net/projects/electricdss/","Official site") -> Official site | K14: =HYPERLINK("https://sourceforge.net/projects/electricdss/files/OpenDSSCmd/license.txt/download","Evidence / lead") -> Evidence / lead | L14: =HYPERLINK("https://sourceforge.net/projects/electricdss/files/OpenDSS/","Language source") -> Language source
A15: E01 | B15: pandapower | C15: O | D15: Automated Python-based network studies | E15: Library rather than turnkey desktop suite | F15: Python, using numerical dependencies | G15: Python | H15: Project documentation and repository | I15: Product/family reference | J15: =HYPERLINK("https://www.pandapower.org/","Official site") -> Official site | K15: =HYPERLINK("https://www.pandapower.org/","Evidence / lead") -> Evidence / lead | L15: =HYPERLINK("https://www.pandapower.org/","Language source") -> Language source
A16: E02 | B16: ETAP protection modules | C16: P | D16: Relay coordination and arc-flash workflows | E16: Module and standards edition matter | F16: Hypothesis: C/C++ and/or Fortran numerical kernels; mixed UI | G16: Product-specific scripting, UDFs and input decks | H16: Architecture hypothesis only | I16: Product/family reference | J16: =HYPERLINK("https://etap.com/","Official site") -> Official site | K16: =HYPERLINK("https://etap.com/solutions/power-system-analysis-optimization","Evidence / lead") -> Evidence / lead | L16: =HYPERLINK("https://www.ansys.com/products","Language source") -> Language source
A17: E02 | B17: SKM PowerTools CAPTOR and A_Fault | C17: P | D17: Time-current and arc-flash studies | E17: Device data and settings require review | F17: Hypothesis: C/C++ and/or Fortran numerical kernels; mixed UI | G17: Product-specific scripting, UDFs and input decks | H17: Architecture hypothesis only | I17: Product/family reference | J17: =HYPERLINK("https://www.skm.com/","Official site") -> Official site | K17: =HYPERLINK("https://www.skm.com/","Evidence / lead") -> Evidence / lead | L17: =HYPERLINK("https://www.ansys.com/products","Language source") -> Language source
A18: E02 | B18: EasyPower | C18: P | D18: Facility electrical safety studies | E18: Check supported calculation standards | F18: Hypothesis: C/C++ and/or Fortran numerical kernels; mixed UI | G18: Product-specific scripting, UDFs and input decks | H18: Architecture hypothesis only | I18: Product/family reference | J18: =HYPERLINK("https://www.easypower.com/","Official site") -> Official site | K18: =HYPERLINK("https://www.easypower.com/","Evidence / lead") -> Evidence / lead | L18: =HYPERLINK("https://www.ansys.com/products","Language source") -> Language source
A19: E02 | B19: DIgSILENT PowerFactory protection | C19: P | D19: Protection within a network model | E19: Specialized relay models need validation | F19: Hypothesis: C/C++ and/or Fortran numerical kernels; mixed UI | G19: Product-specific scripting, UDFs and input decks | H19: Architecture hypothesis only | I19: Product/family reference | J19: =HYPERLINK("https://www.digsilent.de/en/functions.html","Official site") -> Official site | K19: =HYPERLINK("https://www.digsilent.de/en/faq-reader-powerfactory/where-can-i-get-an-overview-list-showing-all-powerfactory-functions.html","Evidence / lead") -> Evidence / lead | L19: =HYPERLINK("https://www.ansys.com/products","Language source") -> Language source
A20: E02 | B20: ASPEN OneLiner | C20: P | D20: Fault and relay studies | E20: Not a general CAD or EMT environment | F20: Hypothesis: C/C++ and/or Fortran numerical kernels; mixed UI | G20: Product-specific scripting, UDFs and input decks | H20: Architecture hypothesis only | I20: Product/family reference | J20: =HYPERLINK("https://www.aspeninc.com/","Official site") -> Official site | K20: =HYPERLINK("https://www.aspeninc.com/","Evidence / lead") -> Evidence / lead | L20: =HYPERLINK("https://www.ansys.com/products","Language source") -> Language source
A21: E02 | B21: CAPE | C21: P | D21: Utility protection engineering | E21: Utility-scale setup and licensing | F21: Hypothesis: C/C++ and/or Fortran numerical kernels; mixed UI | G21: Product-specific scripting, UDFs and input decks | H21: Architecture hypothesis only | I21: Vendor-level reference | J21: =HYPERLINK("https://www.siemens.com/","Official site") -> Official site | K21: =HYPERLINK("https://www.siemens.com/en-gb/products/tia-portal/step7/","Evidence / lead") -> Evidence / lead | L21: =HYPERLINK("https://www.ansys.com/products","Language source") -> Language source
A22: E02 | B22: CYME protection modules | C22: P | D22: Distribution coordination | E22: Module availability varies | F22: Hypothesis: C/C++ and/or Fortran numerical kernels; mixed UI | G22: Product-specific scripting, UDFs and input decks | H22: Architecture hypothesis only | I22: Candidate: direct verification pending | J22: =HYPERLINK("https://www.cyme.com/","Official site") -> Official site | K22: =HYPERLINK("https://www.cyme.com/","Evidence / lead") -> Evidence / lead | L22: =HYPERLINK("https://www.ansys.com/products","Language source") -> Language source
A23: E02 | B23: NEPLAN protection | C23: P | D23: Network fault and protection analysis | E23: Verify relay library coverage | F23: Hypothesis: C/C++ and/or Fortran numerical kernels; mixed UI | G23: Product-specific scripting, UDFs and input decks | H23: Architecture hypothesis only | I23: Candidate: direct verification pending | J23: =HYPERLINK("https://www.neplan.ch/","Official site") -> Official site | K23: =HYPERLINK("https://www.neplan.ch/","Evidence / lead") -> Evidence / lead | L23: =HYPERLINK("https://www.ansys.com/products","Language source") -> Language source
A24: E02 | B24: ERACS | C24: P | D24: Industrial fault and protection studies | E24: Check current modules and standards | F24: Hypothesis: C/C++ and/or Fortran numerical kernels; mixed UI | G24: Product-specific scripting, UDFs and input decks | H24: Architecture hypothesis only | I24: Candidate: direct verification pending | J24: =HYPERLINK("https://www.eracs.co.uk/","Official site") -> Official site | K24: =HYPERLINK("https://www.eracs.co.uk/","Evidence / lead") -> Evidence / lead | L24: =HYPERLINK("https://www.ansys.com/products","Language source") -> Language source
A25: E02 | B25: DIgSILENT StationWare | C25: P | D25: Protection settings management | E25: Companion database, not a fault solver | F25: Hypothesis: C/C++ and/or Fortran numerical kernels; mixed UI | G25: Product-specific scripting, UDFs and input decks | H25: Architecture hypothesis only | I25: Product/family reference | J25: =HYPERLINK("https://www.digsilent.de/","Official site") -> Official site | K25: =HYPERLINK("https://www.digsilent.de/en/functions.html","Evidence / lead") -> Evidence / lead | L25: =HYPERLINK("https://www.ansys.com/products","Language source") -> Language source
A26: E03 | B26: PSCAD/EMTDC | C26: P | D26: Grid electromagnetic transients | E26: Generated simulation needs a compiler | F26: Fortran/C simulation compilation path | G26: Graphical models; Fortran/C components | H26: Documented generated-code/runtime path | I26: Product/family reference | J26: =HYPERLINK("https://www.pscad.com/","Official site") -> Official site | K26: =HYPERLINK("https://www.pscad.com/knowledge-base/topic-609/v-","Evidence / lead") -> Evidence / lead | L26: =HYPERLINK("https://www.pscad.com/knowledge-base/article/584","Language source") -> Language source
A27: E03 | B27: EMTP | C27: P | D27: Power-network transient studies | E27: Detailed equipment models required | F27: Hypothesis: C/C++ and/or Fortran numerical kernels; mixed UI | G27: Product-specific scripting, UDFs and input decks | H27: Architecture hypothesis only | I27: Product/family reference | J27: =HYPERLINK("https://www.emtp.com/","Official site") -> Official site | K27: =HYPERLINK("https://www.emtp.com/","Evidence / lead") -> Evidence / lead | L27: =HYPERLINK("https://www.ansys.com/products","Language source") -> Language source
A28: E03 | B28: PLECS | C28: P | D28: Converter and control simulation | E28: Thermal and real-time features vary | F28: Hypothesis: C/C++ and/or Fortran numerical kernels; mixed UI | G28: Product-specific scripting, UDFs and input decks | H28: Architecture hypothesis only | I28: Vendor-level reference | J28: =HYPERLINK("https://www.plexim.com/","Official site") -> Official site | K28: =HYPERLINK("https://www.plexim.com/","Evidence / lead") -> Evidence / lead | L28: =HYPERLINK("https://www.ansys.com/products","Language source") -> Language source
A29: E03 | B29: PSIM | C29: P | D29: Power electronics and motor drives | E29: Check model fidelity for parasitics | F29: Hypothesis: C/C++ and/or Fortran numerical kernels; mixed UI | G29: Product-specific scripting, UDFs and input decks | H29: Architecture hypothesis only | I29: Candidate: direct verification pending | J29: =HYPERLINK("https://altair.com/psim","Official site") -> Official site | K29: =HYPERLINK("https://altair.com/psim","Evidence / lead") -> Evidence / lead | L29: =HYPERLINK("https://www.ansys.com/products","Language source") -> Language source
A30: E03 | B30: Simulink with Simscape Electrical | C30: P | D30: Controls and physical electrical models | E30: Multiple product licenses may be needed | F30: Historic Fortran; commercial rewrite C; R2025a UI HTML/JavaScript | G30: MATLAB; C/C++/Fortran MEX | H30: Documented history, UI and interfaces | I30: Product/family reference | J30: =HYPERLINK("https://www.mathworks.com/products/simscape-electrical.html","Official site") -> Official site | K30: =HYPERLINK("https://www.mathworks.com/company/technical-articles/a-brief-history-of-matlab.html","Evidence / lead") -> Evidence / lead | L30: =HYPERLINK("https://www.mathworks.com/company/technical-articles/a-brief-history-of-matlab.html","Language source") -> Language source
A31: E03 | B31: SIMetrix/SIMPLIS | C31: P | D31: Switching power-supply analysis | E31: Simulator model assumptions differ | F31: Hypothesis: C/C++ and/or Fortran numerical kernels; mixed UI | G31: Product-specific scripting, UDFs and input decks | H31: Architecture hypothesis only | I31: Product/family reference | J31: =HYPERLINK("https://www.simetrix.co.uk/","Official site") -> Official site | K31: =HYPERLINK("https://www.simetrix.co.uk/","Evidence / lead") -> Evidence / lead | L31: =HYPERLINK("https://www.ansys.com/products","Language source") -> Language source
A32: E03 | B32: LTspice | C32: F | D32: SPICE circuit simulation | E32: Freeware, not open source | F32: Hypothesis: C/C++ and/or Fortran numerical kernels; mixed UI | G32: Product-specific scripting, UDFs and input decks | H32: Architecture hypothesis only | I32: Product/family reference | J32: =HYPERLINK("https://www.analog.com/en/resources/design-tools-and-calculators/ltspice-simulator.html","Official site") -> Official site | K32: =HYPERLINK("https://www.analog.com/en/resources/design-tools-and-calculators/ltspice-simulator.html","Evidence / lead") -> Evidence / lead | L32: =HYPERLINK("https://www.ansys.com/products","Language source") -> Language source
A33: E03 | B33: QSPICE | C33: F | D33: Mixed circuit simulation | E33: Freeware, not an open engine | F33: Hypothesis: C/C++ and/or Fortran numerical kernels; mixed UI | G33: Product-specific scripting, UDFs and input decks | H33: Architecture hypothesis only | I33: Product/family reference | J33: =HYPERLINK("https://www.qorvo.com/design-hub/design-tools/interactive/qspice","Official site") -> Official site | K33: =HYPERLINK("https://www.qorvo.com/design-hub/design-tools/interactive/qspice","Evidence / lead") -> Evidence / lead | L33: =HYPERLINK("https://www.ansys.com/products","Language source") -> Language source
A34: E03 | B34: Typhoon HIL toolchain | C34: P | D34: Real-time converter testing | E34: Hardware-coupled workflow | F34: Hypothesis: C/C++ and/or Fortran numerical kernels; mixed UI | G34: Product-specific scripting, UDFs and input decks | H34: Architecture hypothesis only | I34: Product/family reference | J34: =HYPERLINK("https://www.typhoon-hil.com/","Official site") -> Official site | K34: =HYPERLINK("https://www.typhoon-hil.com/","Evidence / lead") -> Evidence / lead | L34: =HYPERLINK("https://www.ansys.com/products","Language source") -> Language source
A35: E03 | B35: RT-LAB | C35: P | D35: Real-time simulation integration | E35: Timing and hardware setup dominate | F35: Hypothesis: C/C++ and/or Fortran numerical kernels; mixed UI | G35: Product-specific scripting, UDFs and input decks | H35: Architecture hypothesis only | I35: Vendor-level reference | J35: =HYPERLINK("https://www.opal-rt.com/","Official site") -> Official site | K35: =HYPERLINK("https://www.opal-rt.com/","Evidence / lead") -> Evidence / lead | L35: =HYPERLINK("https://www.ansys.com/products","Language source") -> Language source
A36: E04 | B36: MATLAB Control System Toolbox | C36: P | D36: Control analysis and design | E36: Requires MATLAB and relevant add-ons | F36: Historic Fortran; commercial rewrite C; R2025a UI HTML/JavaScript | G36: MATLAB; C/C++/Fortran MEX | H36: Documented history, UI and interfaces | I36: Product/family reference | J36: =HYPERLINK("https://www.mathworks.com/products/control.html","Official site") -> Official site | K36: =HYPERLINK("https://www.mathworks.com/company/technical-articles/a-brief-history-of-matlab.html","Evidence / lead") -> Evidence / lead | L36: =HYPERLINK("https://www.mathworks.com/company/technical-articles/a-brief-history-of-matlab.html","Language source") -> Language source
A37: E04 | B37: Simulink | C37: P | D37: Block-diagram dynamic simulation | E37: Solver and sample-time choices matter | F37: Historic Fortran; commercial rewrite C; R2025a UI HTML/JavaScript | G37: MATLAB; C/C++/Fortran MEX | H37: Documented history, UI and interfaces | I37: Product/family reference | J37: =HYPERLINK("https://www.mathworks.com/products/simulink.html","Official site") -> Official site | K37: =HYPERLINK("https://www.mathworks.com/company/technical-articles/a-brief-history-of-matlab.html","Evidence / lead") -> Evidence / lead | L37: =HYPERLINK("https://www.mathworks.com/company/technical-articles/a-brief-history-of-matlab.html","Language source") -> Language source
A38: E04 | B38: LabVIEW | C38: P | D38: Control experiments and instrumentation | E38: Real-time deployment needs matching platform | F38: Hypothesis: C/C++ and/or Fortran numerical kernels; mixed UI | G38: Product-specific scripting, UDFs and input decks | H38: Architecture hypothesis only | I38: Product/family reference | J38: =HYPERLINK("https://www.ni.com/en/shop/labview.html","Official site") -> Official site | K38: =HYPERLINK("https://www.ni.com/en/support/documentation/supplemental/10/ni-labview-compiler--under-the-hood.html","Evidence / lead") -> Evidence / lead | L38: =HYPERLINK("https://www.ansys.com/products","Language source") -> Language source
A39: E04 | B39: Simcenter Amesim | C39: P | D39: Control with physical system models | E39: Library and license scope varies | F39: Hypothesis: C/C++ and/or Fortran numerical kernels; mixed UI | G39: Product-specific scripting, UDFs and input decks | H39: Architecture hypothesis only | I39: Product/family reference | J39: =HYPERLINK("https://www.siemens.com/en-us/products/simcenter/","Official site") -> Official site | K39: =HYPERLINK("https://www.siemens.com/en-us/products/simcenter/simcenter-x/advanced/","Evidence / lead") -> Evidence / lead | L39: =HYPERLINK("https://www.ansys.com/products","Language source") -> Language source
A40: E04 | B40: MapleSim | C40: P | D40: Symbolic and physical modelling | E40: Not interchangeable with every toolbox | F40: Hypothesis: C/C++ and/or Fortran numerical kernels; mixed UI | G40: Product-specific scripting, UDFs and input decks | H40: Architecture hypothesis only | I40: Product/family reference | J40: =HYPERLINK("https://www.maplesoft.com/products/maplesim/","Official site") -> Official site | K40: =HYPERLINK("https://www.maplesoft.com/products/maplesim/","Evidence / lead") -> Evidence / lead | L40: =HYPERLINK("https://www.ansys.com/products","Language source") -> Language source
A41: E04 | B41: Wolfram System Modeler | C41: P | D41: Modelica-based system dynamics | E41: Ecosystem differs from Simulink | F41: Hypothesis: C/C++ and/or Fortran numerical kernels; mixed UI | G41: Product-specific scripting, UDFs and input decks | H41: Architecture hypothesis only | I41: Product/family reference | J41: =HYPERLINK("https://www.wolfram.com/system-modeler/","Official site") -> Official site | K41: =HYPERLINK("https://www.wolfram.com/system-modeler/","Evidence / lead") -> Evidence / lead | L41: =HYPERLINK("https://www.ansys.com/products","Language source") -> Language source
A42: E04 | B42: Scilab/Xcos | C42: O | D42: Open numerical and block-diagram analysis | E42: Toolbox compatibility is incomplete | F42: Public-source project; language mix not audited in this pass | G42: See project language/API documentation | H42: Implementation check pending | I42: Product/family reference | J42: =HYPERLINK("https://www.scilab.org/","Official site") -> Official site | K42: =HYPERLINK("https://www.scilab.org/","Evidence / lead") -> Evidence / lead | L42: =HYPERLINK("https://www.scilab.org/","Language source") -> Language source
...

Sheet Field map
A1: Engineering and IT fields with their foundations
A3: Fields | B3: =COUNTA(A6:A153) -> 48 | D3: Science and methods describe the field, not every listed product.
A5: Field ID | B5: Branch | C5: Subfield | D5: Scope | E5: Fundamental science | F5: Computational methods | G5: Failure modes / limits | H5: Open foundations to investigate | I5: Proposed first open product | J5: Verification / validation targets | K5: Entries
A6: E01 | B6: Electrical | C6: Power systems and load flow | D6: Transmission, distribution and industrial networks; voltage, loading, losses, contingencies and dispatch. | E6: Kirchhoff laws, complex power, per-unit quantities and network admittance. Bus injections obey S_i = V_i conjugate(sum_j Y_ij V_j). | F6: Newton–Raphson and sparse linear algebra; backward/forward sweep for suitable radial models; constrained nonlinear optimization for AC optimal power flow. | G6: A converged solution can still use wrong load models, transformer connections or operating limits. Unbalanced feeders need phase-aware models; ordinary load flow does not resolve switching transients. | H6: pandapower; OpenDSS; MATPOWER; GridCal; PyPSA for planning and optimization. | I6: A local-first single-line editor with load flow, voltage-drop plots, scenario comparison and a reproducible calculation report. | J6: Hand-solved two-bus case, public IEEE feeder cases, transformer phase shifts, disconnected islands and an independent solver comparison. | K6: =COUNTIF(Catalogue!$A:$A,A6) -> 10
A7: E02 | B7: Electrical | C7: Protection, faults and coordination | D7: Short-circuit duties, relay selectivity, breaker coordination, arc-flash studies and protection settings. | E7: Symmetrical components, sequence networks, equipment withstand, inverse-time curves and empirical arc-energy models. | F7: Fault-network solves; curve intersections; time-current plotting; rule and standards evaluation. | G7: Settings, CT saturation, grounding and upstream timing errors change conclusions. Arc-flash results are sensitive to fault current and clearing time. Standards and device curves are separately versioned data. | H7: pandapower short-circuit functions; OpenDSS fault and protection models; independently licensed curve databases. | I7: A coordination-curve workbench with explicit assumptions and versioned device data; add standards-specific calculations only after verification. | J7: Published reference fault cases, relay manufacturer curve points, pickup boundaries and independent review of units and clearing-time selection. | K7: =COUNTIF(Catalogue!$A:$A,A7) -> 10
A8: E03 | B8: Electrical | C8: Power electronics and electromagnetic transients | D8: Converters, inverters, switching, insulation transients, grid-forming controls and hardware-in-the-loop. | E8: Kirchhoff equations coupled to semiconductor, inductor and capacitor models: v=L di/dt and i=C dv/dt; nonlinear differential-algebraic equations. | F8: Modified nodal analysis, implicit integration, switch-event handling, averaged converter models and fixed-step real-time execution. | G8: Averaged models omit switching ripple; fine switching models can be expensive and stiff. Real-time execution adds deadline constraints, not automatic physical fidelity. | H8: ngspice; Xyce; OpenModelica; Julia/SciML for custom models. | I8: An offline converter workbench with loss-aware averaged and switching models and clear comparisons between them. | J8: Buck-converter analytical limits, RLC step response, timestep refinement, energy balance and measured switching traces. | K8: =COUNTIF(Catalogue!$A:$A,A8) -> 10
A9: E04 | B9: Electrical | C9: Control engineering and system identification | D9: Feedback design, tuning, estimation, model fitting, stability, optimal control and model-based implementation. | E9: State-space models x_dot=Ax+Bu, y=Cx+Du; transfer functions; feedback stability; probability and constrained optimization. | F9: Eigenvalue analysis, frequency response, numerical integration, least squares, Kalman filtering, LQR and model predictive control. | G9: Linearization is local. Delays, saturation, sample time, noise and actuator limits can defeat a design that looks excellent in a nominal simulation. | H9: python-control; SciPy; SLICOT; CasADi; do-mpc; Scilab/Xcos; OpenModelica. | I9: An interactive plant-identification and PID/state-space design tool with reusable experiments and exportable models. | J9: Analytical first/second-order systems, delayed plants, saturation and anti-windup cases, parameter uncertainty and held-out identification data. | K9: =COUNTIF(Catalogue!$A:$A,A9) -> 10
A10: E05 | B10: Electrical | C10: PLC and industrial automation | D10: Machine sequences, interlocks, motion, I/O configuration, commissioning and deterministic execution. | E10: Finite-state machines, Boolean logic, cyclic and event tasks, discrete control and real-time scheduling. | F10: IEC 61131 programming, compilation, scan-cycle execution, online monitoring and device/protocol mapping. | G10: A simulator does not reproduce every device, fieldbus or timing behavior. Safety runtimes, online changes and hardware support are separate engineering problems. | H10: OpenPLC; Beremiz; Eclipse 4diac for IEC 61499; open protocol stacks where licenses fit. | I10: An offline PLC learning and testing environment with simulated I/O, test traces and vendor-neutral project exports. | J10: Scan-order tests, timer semantics, restart states, dropped communications and deterministic timing on the intended runtime. | K10: =COUNTIF(Catalogue!$A:$A,A10) -> 10
A11: E06 | B11: Electrical | C11: SCADA, HMI and industrial data | D11: Supervisory screens, tags, alarms, historians, gateways, trends and plant-data integration. | E11: Distributed state, timestamped events, sampled signals, quality flags, alarm state machines and time-series storage. | F11: Polling and subscriptions, protocol drivers, event processing, database queries and rendering; not primarily a PDE solver. | G11: Clock errors, stale values, alarm flooding and missing quality metadata can mislead operators. A dashboard without device semantics is not a full SCADA platform. | H11: Node-RED plus a historian and HMI components; Eclipse Milo/open62541; FUXA; Rapid SCADA, with component-level license review. | I11: A read-only Modbus/OPC UA monitoring workbench with tag mapping, timestamps, signal quality and exportable trends. | J11: Communication outages, stale-data display, restart/replay behavior, alarm ordering and timestamp consistency. | K11: =COUNTIF(Catalogue!$A:$A,A11) -> 10
A12: E07 | B12: Electrical | C12: Electrical CAD, wiring and building electrical design | D12: Schematics, panel layouts, cable schedules, wire numbering, bills of materials and installation calculations. | E12: Graph connectivity, symbol semantics, geometric constraints, wiring rules and equipment metadata. | F12: Connectivity checking, automatic cross-references, graph traversal, cable rules and document generation. | G12: Drawing lines is easier than preserving electrical connectivity. Vendor symbol libraries and correct revision propagation are a large part of product value. | H12: QElectroTech; FreeCAD; KiCad for electronic schematics; a separately designed electrical data schema. | I12: A wiring and panel documentation tool with reusable symbols, automatic wire lists and consistent revisions. | J12: Round-trip exports, changed terminal numbers, duplicate references, disconnected wires and bill-of-material reconciliation. | K12: =COUNTIF(Catalogue!$A:$A,A12) -> 10
A13: E08 | B13: Electrical | C13: Renewables, storage and energy planning | D13: PV yield, wind resources, microgrids, batteries, dispatch and techno-economic scenarios. | E13: Solar geometry, irradiance, electrical conversion, turbine curves, storage energy balance and discounted cash flow. | F13: Time-series simulation, weather interpolation, loss chains, dispatch optimization and stochastic scenarios. | G13: Weather quality and tariff assumptions can dominate accuracy. Annual energy alone hides curtailment, intermittency and battery degradation. | H13: SAM; pvlib; PyPSA; OpenDSS; REopt API/source components after license checks. | I13: A PV-and-battery feasibility tool with transparent hourly dispatch, editable loss assumptions and uncertainty ranges. | J13: Energy conservation, known PV reference cases, measured monthly yield and dispatch under zero/negative prices and battery limits. | K13: =COUNTIF(Catalogue!$A:$A,A13) -> 10
A14: N01 | B14: Electronics | C14: Analog and mixed-signal circuits | D14: Amplifiers, filters, sensor circuits, power supplies, semiconductor devices and mixed analog/digital behavior. | E14: KCL/KVL plus nonlinear device equations; modified nodal equations G(x)x+C(x)x_dot=b. | F14: Newton iterations, DC operating point, AC linearization, transient integration and Monte Carlo variation. | G14: Convergence does not validate device models. Parasitics, operating temperature, manufacturing variation and encrypted vendor models limit portability. | H14: ngspice; Xyce; Qucs-S; KiCad schematic integration. | I14: A schematic-to-ngspice workbench with model provenance, tolerance sweeps and explainable convergence failures. | J14: RC/RLC analytical circuits, diode operating points, oscillator startup, timestep convergence and measured board behavior. | K14: =COUNTIF(Catalogue!$A:$A,A14) -> 10
A15: N02 | B15: Electronics | C15: PCB design and electronic packaging | D15: Schematic capture, component placement, routing, footprints, clearances and fabrication outputs. | E15: Graph connectivity, computational geometry, impedance constraints, manufacturing tolerances and stack-up models. | F15: Constraint checking, interactive routing, geometric collision tests and format conversion; field solvers handle detailed SI/PI. | G15: A correct netlist does not imply signal integrity or manufacturability. Libraries, stackups and fabrication rules must be trustworthy. | H15: KiCad; LibrePCB; open fabrication formats and independently maintained footprint libraries. | I15: Contribute workflow improvements to KiCad or build a focused review/DFM companion rather than another full PCB editor. | J15: Gerber/drill round trips, netlist consistency, clearance boundaries, footprint pin mapping and manufacturer fabrication checks. | K15: =COUNTIF(Catalogue!$A:$A,A15) -> 10
A16: N03 | B16: Electronics | C16: RF, antennas and electromagnetic compatibility | D16: Antennas, microwave components, waveguides, scattering, electromagnetic coupling and high-frequency packaging. | E16: Maxwell equations, wave propagation, boundary conditions, S-parameters and material dispersion. | F16: Finite elements, finite-difference time domain, method of moments, integral equations and hybrid ray methods. | G16: Mesh dispersion, port definitions, absorbing boundaries and material data can dominate error. No single EM formulation is best at every electrical size. | H16: openEMS; Meep; GetDP/Gmsh; scuff-em. | I16: An antenna workbench for a bounded geometry family with meshing presets, convergence checks and S-parameter reports. | J16: Dipole and waveguide analytical limits, scattering reference cases, mesh refinement and measured S-parameters. | K16: =COUNTIF(Catalogue!$A:$A,A16) -> 10
A17: N04 | B17: Electronics | C17: Signals, communications and DSP | D17: Sampling, filters, modulation, coding, channel models, SDR and signal processing chains. | E17: Fourier/z transforms, convolution, sampling theory, probability, estimation and information theory. | F17: FFT, FIR/IIR filtering, multirate processing, Monte Carlo BER estimation and streaming dataflow. | G17: Ideal simulations omit quantization, clipping, synchronization, oscillator drift and real RF impairments. Reproducible random seeds and units matter. | H17: GNU Radio; SciPy; liquid-dsp; FFTW; JuliaDSP. | I17: A visual DSP lab with inspectable blocks, recorded datasets and a reproducible code export. | J17: FFT normalization, filter response, analytical AWGN BER, aliasing cases and sample-rate/latency tests. | K17: =COUNTIF(Catalogue!$A:$A,A17) -> 10
... A53: I12 | B53: Information technology | C53: IT service management, assets and documentation | D53: Incident, request, change and problem management; asset registers; documentation and knowledge. | E53: Queueing and service levels, workflow state machines and configuration-item relationship graphs. | F53: Ticket workflows; SLA timers; CMDB relationships; discovery; knowledge search. | G53: A CMDB decays without discovery. Heavy process burdens small teams. SaaS platforms can lock in service history. | H53: GLPI; Zammad; Snipe-IT; iTop; BookStack; NetBox for network assets. | I53: A lightweight field-service and asset system for engineering contractors: site assets, visit logs, calibration records and client reports. | J53: Workflow transitions, SLA timer accuracy, asset import round trips and audit-trail completeness. | K53: =COUNTIF(Catalogue!$A:$A,A53) -> 10

Sheet Languages
A1: Implementation languages: evidence and hypotheses
A3: Core, scripting and generated-code languages are different claims.
A5: Product / component | B5: Implementation evidence | C5: User / extension languages | D5: Evidence class | E5: Boundary / uncertainty | F5: Primary reference
A6: MATLAB | B6: Historic Fortran; commercial rewrite C; R2025a UI HTML/JavaScript | C6: MATLAB; C/C++/Fortran MEX | D6: Documented history, UI and interfaces | E6: Complete modern internal language mix not established | F6: =HYPERLINK("https://www.mathworks.com/company/technical-articles/a-brief-history-of-matlab.html","Primary reference") -> Primary reference
A7: MATLAB desktop | B7: Java historically; HTML/JavaScript in R2025a rebuild | C7: MATLAB | D7: Documented implementation component | E7: Does not identify the numerical engine language | F7: =HYPERLINK("https://blogs.mathworks.com/matlab/2025/05/16/whats-with-all-the-big-changes-in-r2025a/","Primary reference") -> Primary reference
A8: Ignition | B8: Java platform | C8: Python via Jython; SQL | D8: Documented platform and scripting | E8: Do not infer every module or browser component is Java | F8: =HYPERLINK("https://www.docs.inductiveautomation.com/docs/8.3/platform","Primary reference") -> Primary reference
A9: PSCAD/EMTDC | B9: Fortran/C simulation compilation path | C9: Graphical models; Fortran/C components | D9: Documented generated-code/runtime path | E9: Does not establish PSCAD GUI implementation | F9: =HYPERLINK("https://www.pscad.com/knowledge-base/article/584","Primary reference") -> Primary reference
A10: Ansys Fluent | B10: Closed core; C/C++ is a plausible native-core hypothesis | C10: C/C++ UDFs | D10: Documented interface; core hypothesis | E10: UDF language is not a complete core-language inventory | F10: =HYPERLINK("https://ansyshelp.ansys.com/public/Views/Secured/corp/v242/en/flu_udf/flu_udf_WhatIsAUDF.html","Primary reference") -> Primary reference
A11: SIMULIA Abaqus | B11: Closed core; C/C++/Fortran are plausible solver languages | C11: Python scripting; C/C++/Fortran user subroutines | D11: Documented interfaces; core hypothesis | E11: Subsystem-by-subsystem implementation remains unverified | F11: =HYPERLINK("https://docs.software.vt.edu/abaqusv2025/English/SIMACAESUBRefMap/simasub-c-subroutineover.htm","Primary reference") -> Primary reference
A12: FreeCAD | B12: C++ and Python | C12: Python | D12: Direct public source documentation | E12: Plugins and bundled libraries have their own implementations | F12: =HYPERLINK("https://www.freecad.org/api/","Primary reference") -> Primary reference
A13: KiCad | B13: C++ components; Python integration | C13: Python interfaces; schematic/PCB formats | D13: Direct public source documentation | E13: Library data licensing differs from application licensing | F13: =HYPERLINK("https://docs.kicad.org/doxygen/python__manager_8cpp_source.html","Primary reference") -> Primary reference
A14: OpenFOAM | B14: C++ | C14: C++ extensions; case dictionaries | D14: Direct public source documentation | E14: Choose a particular distribution and release | F14: =HYPERLINK("https://openfoam.org/resources/","Primary reference") -> Primary reference
A15: OpenDSS | B15: Delphi/Object Pascal; Free Pascal in OpenDSSCmd | C15: DSS commands; external automation interfaces | D15: Official project distribution documentation | E15: EPRI engine and alternative wrappers are different components | F15: =HYPERLINK("https://sourceforge.net/projects/electricdss/files/OpenDSS/","Primary reference") -> Primary reference
A16: pandapower | B16: Python, using numerical dependencies | C16: Python | D16: Project documentation and repository | E16: Python front end can call compiled numerical libraries | F16: =HYPERLINK("https://www.pandapower.org/","Primary reference") -> Primary reference
A17: PyPSA | B17: Python with external numerical/optimization dependencies | C17: Python | D17: Project documentation | E17: Optimization solver is a separately selected dependency | F17: =HYPERLINK("https://pypsa.org/","Primary reference") -> Primary reference
A18: OpenModelica | B18: MetaModelica compiler architecture; generated C/C++ runtime paths | C18: Modelica; scripting/interfaces | D18: Official compiler documentation | E18: Compiler, runtime and model-library licenses differ | F18: =HYPERLINK("https://openmodelica.org/doc/OpenModelicaUsersGuide/1.26/compiler.html","Primary reference") -> Primary reference
A19: EPANET | B19: C engine | C19: Network input files; C toolkit and wrappers | D19: Official source repository | E19: Engine implementation does not identify every GUI or fork | F19: =HYPERLINK("https://github.com/USEPA/epanet-engine","Primary reference") -> Primary reference
A20: EPA SWMM | B20: C engine | C20: SWMM model files; APIs/wrappers | D20: Official source repository | E20: Separate GUI and community forks need separate checks | F20: =HYPERLINK("https://github.com/USEPA/Stormwater-Management-Model","Primary reference") -> Primary reference
A21: Project Chrono | B21: C++ | C21: C++; Python bindings | D21: Official implementation statement | E21: Bindings and optional modules introduce dependencies | F21: =HYPERLINK("https://www.projectchrono.org/","Primary reference") -> Primary reference
A22: GHDL | B22: Ada and C | C22: VHDL | D22: Official repository and build documentation | E22: HDL being simulated is distinct from simulator language | F22: =HYPERLINK("https://github.com/ghdl/ghdl","Primary reference") -> Primary reference
A23: SimPy | B23: Python | C23: Python | D23: Official documentation | E23: Process/event model, not a continuous physics solver | F23: =HYPERLINK("https://simpy.readthedocs.io/","Primary reference") -> Primary reference
A24: GNU Octave | B24: Public compiled implementation; detailed mix not audited here | C24: Octave language; native extensions | D24: Official source and extension documentation | E24: C/C++/Fortran extension support alone is not a source inventory | F24: =HYPERLINK("https://octave.org/about","Primary reference") -> Primary reference
A25: ngspice | B25: Public SPICE implementation; full language mix not audited here | C25: SPICE netlists and control language; C shared-library interface | D25: Official developer/interface documentation | E25: Source availability is stronger evidence than a guessed commercial lineage | F25: =HYPERLINK("https://ngspice.sourceforge.io/faq.html","Primary reference") -> Primary reference
A26: EnergyPlus | B26: Public source; native simulation engine | C26: Input models; C/Python APIs | D26: Official project repository | E26: API language alone does not prove complete source mix | F26: =HYPERLINK("https://github.com/NatLabRockies/EnergyPlus","Primary reference") -> Primary reference
A27: RoboDK | B27: Closed engine; implementation unknown in this study | C27: Python and other API clients; robot-specific output | D27: Documented API only | E27: Python API does not establish a Python implementation | F27: =HYPERLINK("https://robodk.com/doc/en/RoboDK-API.html","Primary reference") -> Primary reference
A28: TIA Portal / Studio 5000 / PLC IDE family | B28: Unknown; native compiler/runtime with desktop or web UI is plausible | C28: IEC 61131 languages; vendor-specific features | D28: Architecture hypothesis only | E28: Do not treat ladder/ST as the IDE implementation language | F28: =HYPERLINK("https://www.siemens.com/en-gb/products/tia-portal/step7/","Primary reference") -> Primary reference
A29: Commercial CAD family | B29: Hypothesis: native C++ geometry; UI stack varies | C29: Product-specific scripting and APIs | D29: Architecture hypothesis only | E29: Kernel lineage and API languages need product-specific verification | F29: =HYPERLINK("https://www.ptc.com/en/products/creo","Primary reference") -> Primary reference
A30: Commercial FEA/CFD family | B30: Hypothesis: C/C++ and/or Fortran numerical kernels; mixed UI | C30: Product-specific scripting, UDFs and input decks | D30: Architecture hypothesis only | E30: No product-by-product source access was obtained | F30: =HYPERLINK("https://www.ansys.com/products","Primary reference") -> Primary reference
A31: Commercial EDA family | B31: Hypothesis: C/C++ performance-sensitive engines; mixed scripting/UI | C31: HDLs, SPICE, Tcl or vendor DSLs depending on tool | D31: Architecture hypothesis only | E31: Different stages in a suite are separate programs | F31: =HYPERLINK("https://www.cadence.com/en_US/home/tools.html","Primary reference") -> Primary reference
A32: Wireshark | B32: C | C32: Lua dissectors; C plugins | D32: Public repository language; recheck at chosen release | E32: Capture library (libpcap/Npcap) is a separate component | F32: =HYPERLINK("https://gitlab.com/wireshark/wireshark","Primary reference") -> Primary reference
A33: Zabbix | B33: C server; PHP frontend; Go agent 2 | C33: Templates; JavaScript preprocessing | D33: Public repository language; recheck at chosen release | E33: Components use different languages; AGPL since version 7 | F33: =HYPERLINK("https://github.com/zabbix/zabbix","Primary reference") -> Primary reference
A34: Prometheus | B34: Go | C34: PromQL; exporters in any language | D34: Public repository language; recheck at chosen release | E34: Grafana is a separate AGPL project | F34: =HYPERLINK("https://github.com/prometheus/prometheus","Primary reference") -> Primary reference
A35: NetBox | B35: Python (Django) | C35: Python scripts; REST and GraphQL | D35: Public repository language; recheck at chosen release | E35: Hosted editions add commercial components | F35: =HYPERLINK("https://github.com/netbox-community/netbox","Primary reference") -> Primary reference
A36: Ansible | B36: Python | C36: YAML playbooks; Jinja2; Python modules | D36: Public repository language; recheck at chosen release | E36: Collections are separately maintained and licensed | F36: =HYPERLINK("https://github.com/ansible/ansible","Primary reference") -> Primary reference
A37: Batfish | B37: Java | C37: Python client | D37: Public repository language; recheck at chosen release | E37: Parser coverage differs by vendor | F37: =HYPERLINK("https://github.com/batfish/batfish","Primary reference") -> Primary reference
A38: Suricata | B38: C and Rust | C38: Suricata rules; Lua | D38: Public repository language; recheck at chosen release | E38: Rule sets have their own licenses | F38: =HYPERLINK("https://github.com/OISF/suricata","Primary reference") -> Primary reference
A39: Zeek | B39: C++ | C39: Zeek scripting language; Spicy | D39: Public repository language; recheck at chosen release | E39: Script packages are separate projects | F39: =HYPERLINK("https://github.com/zeek/zeek","Primary reference") -> Primary reference
A40: Nmap | B40: C and C++ | C40: Lua (NSE) | D40: Public repository language; recheck at chosen release | E40: Nmap Public Source License restricts proprietary redistribution | F40: =HYPERLINK("https://github.com/nmap/nmap","Primary reference") -> Primary reference
A41: Metasploit Framework | B41: Ruby | C41: Ruby modules | D41: Public repository language; recheck at chosen release | E41: Metasploit Pro is a separate commercial product | F41: =HYPERLINK("https://github.com/rapid7/metasploit-framework","Primary reference") -> Primary reference
A42: OpenVox | B42: Ruby; Clojure server | C42: Puppet language | D42: Public repository language; recheck at chosen release | E42: Community fork; Perforce Puppet is now a separate closed fork | F42: =HYPERLINK("https://github.com/OpenVoxProject/openvox","Primary reference") -> Primary reference
...

Sheet Read me
A1: How to use this research
A3: Research date | B3: 7 October 2026. Current editions, sales status, exact licenses and technical support must be checked before selecting a dependency or purchasing software.
A4: Scope | B4: 48 practical subfields: 36 engineering subfields plus 12 information technology subfields, with ten entries per field. The catalogue has 480 field-tool entries, including repeated families, modules and toolchains.
A5: Top ten means | B5: Unranked research shortlist: relevance, established workflows, specialist capability and value as an open implementation reference. No market-share ranking or hands-on benchmark is claimed.
A6: P | B6: Proprietary commercial product or module.
A7: F | B7: No-cost proprietary software/IDE. Free access does not mean open-source implementation.
A8: O | B8: Open-source project; inspect exact release, dependency and model/data licenses.
A9: M / O/M | B9: Mixed editions, component-dependent terms, or an open core with commercial additions.
A10: S | B10: Source available with restrictions. OpenSees published redistribution terms need particular attention.
A11: Product/family reference | B11: The retrieved public evidence names the product or its family. This does not validate every edition, feature, license term or implementation detail.
A12: Vendor-level reference | B12: An official vendor page was located, but this pass did not establish specific product details from that page.
A13: Candidate: direct verification pending | B13: A credible discovery lead remains; direct product evidence was not established in this retrieval pass. Treat it as a candidate, not a verified current offering.
A14: Known product: source check pending | B14: Used in the IT branch for well-established products named from analyst knowledge. The official link is supplied but was not retrieved in this pass; confirm edition, license and status before relying on it.
... A25: Update method | B25: Preserve the Field ID; update product and evidence cells together. Counts use whole-column formulas, so appended Catalogue rows are counted automatically.
